Workbook

Sheet Summary
A1: Sales data cleanup and reporting
A2: PostgreSQL project on a synthetic e-commerce export. Period: Jan 2024 - Sep 2026. Data extracted 2026-10-06.
A4: Headline numbers
A5: Metric | B5: Value | C5: How it is calculated
A6: Revenue (excluding cancelled orders) | B6: =Monthly!B38 -> 2.9156554e+08 | C6: Sum of monthly revenue
A7: Orders | B7: =Monthly!C38 -> 42285 | C7: Sum of monthly orders
A8: Units sold | B8: =Monthly!D38 -> 137122 | C8: Sum of monthly units
A9: Average order value | B9: =B6/B7 -> 6895.2475 | C9: Revenue / orders
A10: Customers | B10: =Countries!B11 -> 4986 | C10: Sum of customers by country
A11: Repeat customers, share of customers | B11: =1-Segments!B5/Segments!B8 -> 0.97934216 | C11: 1 - one-time customers / all customers
A12: Top category, share of revenue | B12: =MAX(Categories!E5:E10) -> 0.46873701 | C12: Largest category share
A13: Cancelled orders, share of all orders | B13: =7417/49702 -> 0.14922941 | C13: 7,417 cancelled of 49,702 orders in clean.sales_lines
A15: Do the reports agree with each other?
A16: Report | B16: Revenue total | C16: Difference vs monthly total
A17: Monthly | B17: =Monthly!B38 -> 2.9156554e+08 | C17: =ROUND(B17-$B$17,2) -> 0
A18: Categories | B18: =Categories!B11 -> 2.9156554e+08 | C18: =ROUND(B18-$B$17,2) -> 0
A19: Products | B19: =Products!E47 -> 2.9156554e+08 | C19: =ROUND(B19-$B$17,2) -> 0
A20: Countries | B20: =Countries!D11 -> 2.9156554e+08 | C20: =ROUND(B20-$B$17,2) -> 0
A21: Segments | B21: =Segments!D8 -> 2.9156554e+08 | C21: =ROUND(B21-$B$17,2) -> 0
A23: Data cleanup in one glance
A24: Metric | B24: Value | C24: Where to look
A25: Raw rows received | B25: ='Data quality'!B6 -> 102581 | C25: Data quality, block 1
A26: Clean rows delivered | B26: ='Data quality'!B7 -> 100533 | C26: Data quality, block 1
A27: Rows rejected with a reason | B27: ='Data quality'!B8 -> 2048 | C27: Data quality, block 3
A28: Rows lost without explanation | B28: ='Data quality'!B9 -> 0 | C28: Must be 0
A29: Cells corrected and logged | B29: ='Data quality'!B49 -> 43253 | C29: Data quality, block 4
A30: Verification checks passed | B30: =COUNTIF('Data quality'!C53:C63,"PASS") -> 11 | C30: Out of 11; Data quality, block 5
A32: Notes
A33: The dataset is synthetic. It was generated to imitate a messy shop export; no real customers are in it.
A34: Revenue rule: every order except status 'cancelled'. Unpaid orders with status 'new' are included.
A35: Rejected rows are kept in clean.rejects with a reason and are not part of any report.

Sheet Monthly
A1: Monthly sales
A2: Source: view reports.monthly_kpis (PostgreSQL). Revenue = all orders except cancelled. Average order value and growth are Excel formulas.
A4: Month | B4: Revenue | C4: Orders | D4: Units | E4: Customers | F4: Avg order value | G4: Growth vs previous month
A5: 45292 | B5: 8860864.5 | C5: 1292 | D5: 4150 | E5: 1029 | F5: =B5/C5 -> 6858.2543
A6: 45323 | B6: 8268870.7 | C6: 1164 | D6: 3794 | E6: 947 | F6: =B6/C6 -> 7103.8408 | G6: =(B6-B5)/B5 -> -0.06680994
A7: 45352 | B7: 9326088.2 | C7: 1317 | D7: 4352 | E7: 1055 | F7: =B7/C7 -> 7081.3122 | G7: =(B7-B6)/B6 -> 0.12785512
A8: 45383 | B8: 8807429.4 | C8: 1261 | D8: 4090 | E8: 1023 | F8: =B8/C8 -> 6984.4801 | G8: =(B8-B7)/B7 -> -0.055613748
A9: 45413 | B9: 9263004.4 | C9: 1333 | D9: 4315 | E9: 1056 | F9: =B9/C9 -> 6948.9906 | G9: =(B9-B8)/B8 -> 0.051726217
A10: 45444 | B10: 8808141.2 | C10: 1234 | D10: 4105 | E10: 1018 | F10: =B10/C10 -> 7137.8778 | G10: =(B10-B9)/B9 -> -0.049105368
A11: 45474 | B11: 9015219.5 | C11: 1377 | D11: 4453 | E11: 1088 | F11: =B11/C11 -> 6547.0004 | G11: =(B11-B10)/B10 -> 0.023509874
A12: 45505 | B12: 9234290.9 | C12: 1319 | D12: 4212 | E12: 1065 | F12: =B12/C12 -> 7000.9787 | G12: =(B12-B11)/B11 -> 0.024300174
A13: 45536 | B13: 8704798.1 | C13: 1259 | D13: 4123 | E13: 1024 | F13: =B13/C13 -> 6914.0572 | G13: =(B13-B12)/B12 -> -0.057339847
A14: 45566 | B14: 8774614.5 | C14: 1287 | D14: 4199 | E14: 1028 | F14: =B14/C14 -> 6817.8823 | G14: =(B14-B13)/B13 -> 0.008020456
A15: 45597 | B15: 8685499.4 | C15: 1232 | D15: 4056 | E15: 989 | F15: =B15/C15 -> 7049.9184 | G15: =(B15-B14)/B14 -> -0.01015601
A16: 45627 | B16: 9498424.1 | C16: 1349 | D16: 4469 | E16: 1105 | F16: =B16/C16 -> 7041.0853 | G16: =(B16-B15)/B15 -> 0.093595614
A17: 45658 | B17: 9256752.7 | C17: 1352 | D17: 4401 | E17: 1087 | F17: =B17/C17 -> 6846.7106 | G17: =(B17-B16)/B16 -> -0.025443319
... A37: 46266 | B37: 9121302.6 | C37: 1298 | D37: 4177 | E37: 1044 | F37: =B37/C37 -> 7027.1977 | G37: =(B37-B36)/B36 -> -0.049148168
A38: Total | B38: =SUM(B5:B37) -> 2.9156554e+08 | C38: =SUM(C5:C37) -> 42285 | D38: =SUM(D5:D37) -> 137122 | F38: =B38/C38 -> 6895.2475
A39: Customers are not summed: the same customer buys in several months.

Sheet Categories
A1: Sales by category
A2: Source: view reports.category_sales (PostgreSQL).
A4: Category | B4: Revenue | C4: Units | D4: Orders | E4: Share of revenue
A5: Laptops | B5: 1.3666756e+08 | C5: 23010 | D5: 12621 | E5: =B5/SUM($B$5:$B$10) -> 0.46873701
A6: Phones | B6: 88381038 | C6: 22481 | D6: 12448 | E6: =B6/SUM($B$5:$B$10) -> 0.3031258
A7: Monitors | B7: 32284105 | C7: 22571 | D7: 12469 | E7: =B7/SUM($B$5:$B$10) -> 0.11072675
A8: Audio | B8: 20044904 | C8: 23012 | D8: 12680 | E8: =B8/SUM($B$5:$B$10) -> 0.068749223
A9: Smart Home | B9: 10875832 | C9: 23113 | D9: 12628 | E9: =B9/SUM($B$5:$B$10) -> 0.037301499
A10: Accessories | B10: 3312101.9 | C10: 22935 | D10: 12596 | E10: =B10/SUM($B$5:$B$10) -> 0.011359716
A11: Total | B11: =SUM(B5:B10) -> 2.9156554e+08 | C11: =SUM(C5:C10) -> 137122 | E11: =SUM(E5:E10) -> 1
A12: Orders are not summed: one order can contain several categories.

Sheet Products
A1: Product ranking inside each category
A2: Source: view reports.product_ranking (PostgreSQL). Rank and share are Excel formulas.
A4: Category | B4: SKU | C4: Product | D4: Units | E4: Revenue | F4: Rank in category | G4: Share of category
A5: Accessories | B5: SKU-0041 | C5: Accessories model 7 | D5: 3302 | E5: 861953.56 | F5: =1+COUNTIFS($A$5:$A$46,A5,$E$5:$E$46,">"&E5) -> 1 | G5: =E5/SUMIFS($E$5:$E$46,$A$5:$A$46,A5) -> 0.26024367
A6: Accessories | B6: SKU-0011 | C6: Accessories model 2 | D6: 3282 | E6: 611438.77 | F6: =1+COUNTIFS($A$5:$A$46,A6,$E$5:$E$46,">"&E6) -> 2 | G6: =E6/SUMIFS($E$5:$E$46,$A$5:$A$46,A6) -> 0.18460748
A7: Accessories | B7: SKU-0029 | C7: Accessories model 5 | D7: 3243 | E7: 526682.13 | F7: =1+COUNTIFS($A$5:$A$46,A7,$E$5:$E$46,">"&E7) -> 3 | G7: =E7/SUMIFS($E$5:$E$46,$A$5:$A$46,A7) -> 0.15901749
A8: Accessories | B8: SKU-0023 | C8: Accessories model 4 | D8: 3301 | E8: 471880.24 | F8: =1+COUNTIFS($A$5:$A$46,A8,$E$5:$E$46,">"&E8) -> 4 | G8: =E8/SUMIFS($E$5:$E$46,$A$5:$A$46,A8) -> 0.14247154
A9: Accessories | B9: SKU-0017 | C9: Accessories model 3 | D9: 3256 | E9: 360326.72 | F9: =1+COUNTIFS($A$5:$A$46,A9,$E$5:$E$46,">"&E9) -> 5 | G9: =E9/SUMIFS($E$5:$E$46,$A$5:$A$46,A9) -> 0.10879095
A10: Accessories | B10: SKU-0035 | C10: Accessories model 6 | D10: 3266 | E10: 325301.49 | F10: =1+COUNTIFS($A$5:$A$46,A10,$E$5:$E$46,">"&E10) -> 6 | G10: =E10/SUMIFS($E$5:$E$46,$A$5:$A$46,A10) -> 0.098216028
A11: Accessories | B11: SKU-0005 | C11: Accessories model 1 | D11: 3285 | E11: 154518.95 | F11: =1+COUNTIFS($A$5:$A$46,A11,$E$5:$E$46,">"&E11) -> 7 | G11: =E11/SUMIFS($E$5:$E$46,$A$5:$A$46,A11) -> 0.046652838
A12: Audio | B12: SKU-0003 | C12: Audio model 1 | D12: 3352 | E12: 4548974.2 | F12: =1+COUNTIFS($A$5:$A$46,A12,$E$5:$E$46,">"&E12) -> 1 | G12: =E12/SUMIFS($E$5:$E$46,$A$5:$A$46,A12) -> 0.22693919
A13: Audio | B13: SKU-0027 | C13: Audio model 5 | D13: 3288 | E13: 4488712.9 | F13: =1+COUNTIFS($A$5:$A$46,A13,$E$5:$E$46,">"&E13) -> 2 | G13: =E13/SUMIFS($E$5:$E$46,$A$5:$A$46,A13) -> 0.22393287
A14: Audio | B14: SKU-0039 | C14: Audio model 7 | D14: 3284 | E14: 3772355.2 | F14: =1+COUNTIFS($A$5:$A$46,A14,$E$5:$E$46,">"&E14) -> 3 | G14: =E14/SUMIFS($E$5:$E$46,$A$5:$A$46,A14) -> 0.18819522
A15: Audio | B15: SKU-0009 | C15: Audio model 2 | D15: 3321 | E15: 2870334.9 | F15: =1+COUNTIFS($A$5:$A$46,A15,$E$5:$E$46,">"&E15) -> 4 | G15: =E15/SUMIFS($E$5:$E$46,$A$5:$A$46,A15) -> 0.14319524
A16: Audio | B16: SKU-0021 | C16: Audio model 4 | D16: 3236 | E16: 2064076.1 | F16: =1+COUNTIFS($A$5:$A$46,A16,$E$5:$E$46,">"&E16) -> 5 | G16: =E16/SUMIFS($E$5:$E$46,$A$5:$A$46,A16) -> 0.10297261
... A46: Smart Home | B46: SKU-0042 | C46: Smart Home model 7 | D46: 3241 | E46: 243037.64 | F46: =1+COUNTIFS($A$5:$A$46,A46,$E$5:$E$46,">"&E46) -> 7 | G46: =E46/SUMIFS($E$5:$E$46,$A$5:$A$46,A46) -> 0.02234658
A47: Total | D47: =SUM(D5:D46) -> 137122 | E47: =SUM(E5:E46) -> 2.9156554e+08

Sheet Countries
A1: Sales by country
A2: Source: view reports.country_sales (PostgreSQL).
A4: Country | B4: Customers | C4: Orders | D4: Revenue | E4: Avg order value | F4: Share of revenue
A5: Poland | B5: 1328 | C5: 10906 | D5: 74634708 | E5: =D5/C5 -> 6843.4538 | F5: =D5/SUM($D$5:$D$10) -> 0.25597918
A6: Germany | B6: 999 | C6: 8558 | D6: 58971031 | E6: =D6/C6 -> 6890.7491 | F6: =D6/SUM($D$5:$D$10) -> 0.20225652
A7: Ukraine | B7: 663 | C7: 6075 | D7: 41779875 | E7: =D7/C7 -> 6877.3457 | F7: =D7/SUM($D$5:$D$10) -> 0.14329497
A8: Spain | B8: 666 | C8: 5749 | D8: 40009973 | E8: =D8/C8 -> 6959.4666 | F8: =D8/SUM($D$5:$D$10) -> 0.13722463
A9: Netherlands | B9: 665 | C9: 5523 | D9: 38814881 | E9: =D9/C9 -> 7027.8618 | F9: =D9/SUM($D$5:$D$10) -> 0.13312575
A10: Czechia | B10: 665 | C10: 5474 | D10: 37355072 | E10: =D10/C10 -> 6824.0906 | F10: =D10/SUM($D$5:$D$10) -> 0.12811895
A11: Total | B11: =SUM(B5:B10) -> 4986 | C11: =SUM(C5:C10) -> 42285 | D11: =SUM(D5:D10) -> 2.9156554e+08 | E11: =D11/C11 -> 6895.2475 | F11: =SUM(F5:F10) -> 1

Sheet Segments
A1: Customer segments by number of orders
A2: Source: view reports.customer_segments (PostgreSQL).
A4: Segment | B4: Customers | C4: Orders | D4: Revenue | E4: Share of customers | F4: Share of revenue | G4: Revenue per customer
A5: One-time (1 order) | B5: 103 | C5: 103 | D5: 713465.7 | E5: =B5/SUM($B$5:$B$7) -> 0.020657842 | F5: =D5/SUM($D$5:$D$7) -> 0.0024470165 | G5: =D5/B5 -> 6926.8515
A6: Repeat (2-5 orders) | B6: 1851 | C6: 7104 | D6: 48976703 | E6: =B6/SUM($B$5:$B$7) -> 0.37123947 | F6: =D6/SUM($D$5:$D$7) -> 0.16797837 | G6: =D6/B6 -> 26459.591
A7: Loyal (6+ orders) | B7: 3032 | C7: 35078 | D7: 2.4187537e+08 | E7: =B7/SUM($B$5:$B$7) -> 0.60810269 | F7: =D7/SUM($D$5:$D$7) -> 0.82957462 | G7: =D7/B7 -> 79774.199
A8: Total | B8: =SUM(B5:B7) -> 4986 | C8: =SUM(C5:C7) -> 42285 | D8: =SUM(D5:D7) -> 2.9156554e+08 | E8: =SUM(E5:E7) -> 1 | F8: =SUM(F5:F7) -> 1 | G8: =D8/B8 -> 58476.843

Sheet Data quality
A1: Data cleanup: before, after and proof
A2: Sources: 01_data_audit.sql, 02_cleanup.sql, 03_verification.sql. Raw table: raw.sales_export.
A4: 1. Row reconciliation
A5: Metric | B5: Rows
A6: Raw rows in the export | B6: 102581
A7: Clean rows kept | B7: 100533
A8: Rejected rows (with a reason) | B8: =B36 -> 2048
A9: Raw - clean - rejected (must be 0) | B9: =B6-B7-B8 -> 0
A11: 2. Problems found in the raw export
A12: Check | B12: Rows affected | C12: Share of raw rows
A13: Exact duplicate rows (extra copies) | B13: 1221 | C13: =B13/$B$6 -> 0.011902789
A14: Customer email missing | B14: 485 | C14: =B14/$B$6 -> 0.0047279711
A15: Customer email not normalized | B15: 5184 | C15: =B15/$B$6 -> 0.050535674
A16: Country not in standard list | B16: 10926 | C16: =B16/$B$6 -> 0.10651095
A17: City missing | B17: 6558 | C17: =B17/$B$6 -> 0.063929968
A18: Status not in standard list | B18: 11056 | C18: =B18/$B$6 -> 0.10777824
A19: Order date not parseable | B19: 0 | C19: =B19/$B$6 -> 0
A20: Order date not in ISO format | B20: 5488 | C20: =B20/$B$6 -> 0.053499186
A21: Order date in the future | B21: 24 | C21: =B21/$B$6 -> 0.00023396145
A22: Unit price not a plain number | B22: 4133 | C22: =B22/$B$6 -> 0.040290112
A23: Quantity missing or not positive | B23: 478 | C23: =B23/$B$6 -> 0.0046597323
A24: SKU not in product master | B24: 210 | C24: =B24/$B$6 -> 0.0020471627
... A26: Category missing | B26: 1404 | C26: =B26/$B$6 -> 0.013686745
A27: One row can have several problems, so this column is not summed.
A29: 3. Rejected rows by reason
A30: Reason | B30: Rows | C30: Share of raw rows
A31: Exact duplicate of an earlier row | B31: 1221 | C31: =B31/$B$6 -> 0.011902789
A32: Quantity missing or not positive | B32: 474 | C32: =B32/$B$6 -> 0.0046207387
A33: SKU not in product master | B33: 208 | C33: =B33/$B$6 -> 0.0020276659
A34: Customer email missing, not recoverable from the order | B34: 121 | C34: =B34/$B$6 -> 0.0011795557
A35: Order date in the future | B35: 24 | C35: =B35/$B$6 -> 0.00023396145
A36: Total rejected | B36: =SUM(B31:B35) -> 2048 | C36: =B36/$B$6 -> 0.019964711
A38: 4. Change log: cells corrected in the clean data
A39: Column | B39: Cells changed | C39: Rule applied
A40: status | B40: 10823 | C40: trim, lowercase, canceled -> cancelled
A41: country | B41: 10712 | C41: mapped to standard country name
A42: order_date | B42: 5369 | C42: converted to ISO timestamp
A43: customer_email | B43: 5091 | C43: trim, lowercase
A44: unit_price | B44: 4055 | C44: removed currency symbol / decimal comma
A45: product_name | B45: 3848 | C45: replaced with product master name
...
